Workbook

Sheet 1. Executive Dashboard
A1: BlueAlly × AEA AI Portfolio Value Acceleration Dashboard
A2: Generated: 1/29/2026, 12:41:18 PM
A4: PORTFOLIO OVERVIEW
A5: Total Companies | B5: 54
A6: Total Use Cases | B6: 540
A7: Total Annual Value | B7: 388.99362
A8: Average Value/Company | B8: 7.2035856
A10: BENEFIT DISTRIBUTION
A11: Cost Savings | B11: 169.05149
A12: Revenue Growth | B12: 148.10122
A13: Risk Reduction | B13: 65.960392
A14: Cash Flow Acceleration | B14: 57.370511
A16: PRIORITY BREAKDOWN
A17: Critical Priority | B17: 111
A18: High Priority | B18: 247
A19: Medium Priority | B19: 182
A21: TOP 10 USE CASES BY VALUE
A22: Company | B22: Use Case | C22: Total Value ($M) | D22: Priority | E22: Phase
A23: The Lifetime Value Co | B23: Churn Prediction & Intervention Engine | C23: 32.5 | D23: High | E23: Q1
A24: Splash Car Wash | B24: Predictive Member Churn Intervention | C24: 17.4 | D24: High | E24: Q2
A25: Bespoke Partners | B25: Due Diligence Document Analyzer | C25: 17.2 | D25: Critical | E25: Q2
A26: Bespoke Partners | B26: Intelligent CRM Relationship Mapper | C26: 14.7 | D26: High | E26: Q3
A27: Traeger Pellet Grills | B27: Predictive Demand Planning Engine | C27: 12.7 | D27: High | E27: Q2
A28: Splash Car Wash | B28: Single-Wash Membership Conversion Assistant | C28: 12.6 | D28: High | E28: Q2
A29: Splash Car Wash | B29: Equipment Predictive Maintenance Advisor | C29: 11.6 | D29: Medium | E29: Q3
A30: Bespoke Partners | B30: Regulatory Compliance Intelligence System | C30: 10.7 | D30: High | E30: Q3
A31: Traeger Pellet Grills | B31: Customer Feedback Intelligence Platform | C31: 10.7 | D31: High | E31: Q2
A32: Splash Car Wash | B32: Site Selection Decision Support | C32: 10 | D32: Medium | E32: Q3

Sheet 2. Company Master
A1: Rank | B1: Company | C1: Revenue ($M) | D1: Est. EBITDA ($M) | E1: Employees | F1: Total Use Cases | G1: Total Annual Value ($M) | H1: Cost Benefit ($M) | I1: Revenue Benefit ($M) | J1: Risk Benefit ($M) | K1: Cash Flow Benefit ($M) | L1: Value/Token Ratio | M1: Top Priority Count
A2: 1 | B2: AmeriVet Partners | C2: 850 | D2: 85 | E2: 0 | F2: 10 | G2: 200.4 | H2: 98.2 | I2: 82.5 | J2: 12.6 | K2: 7 | L2: 4417 | M2: 3
A3: 2 | B3: Chemtron RiverBend | C3: 892 | D3: 89.2 | E3: 1850 | F3: 10 | G3: 171.1 | H3: 80.5 | I3: 32.1 | J3: 37.3 | K3: 21.2 | L3: 12.58 | M3: 2
A4: 3 | B4: Monroe Engineering | C4: 847 | D4: 84.7 | E4: 3200 | F4: 10 | G4: 166.3 | H4: 71.1 | I4: 13.6 | J4: 24.9 | K4: 56.7 | L4: 15700 | M4: 3
A5: 4 | B5: NES Fircroft | C5: 850 | D5: 85 | E5: 4000 | F5: 10 | G5: 154.5 | H5: 73.9 | I5: 39.6 | J5: 23.5 | K5: 17.5 | L5: 32870 | M5: 9
A6: 5 | B6: American Dental | C6: 450 | D6: 45 | E6: 0 | F6: 10 | G6: 153.8 | H6: 47.3 | I6: 76.8 | J6: 9.4 | K6: 21.3 | L6: 5542 | M6: 3
A7: 6 | B7: Polygon Group | C7: 890 | D7: 89 | E7: 1850 | F7: 10 | G7: 153.8 | H7: 92.3 | I7: 28.5 | J7: 13.6 | K7: 19.4 | L7: 1203000 | M7: 4
A8: 7 | B8: Numotion | C8: 1800 | D8: 180 | E8: 3500 | F8: 10 | G8: 126.9 | H8: 56.6 | I8: 13.2 | J8: 9.9 | K8: 48.5 | L8: 10.9 | M8: 1
A9: 8 | B9: Rees Scientific | C9: 890 | D9: 89 | E9: 3200 | F9: 10 | G9: 124.8 | H9: 23.6 | I9: 72.7 | J9: 13.6 | K9: 14.9 | L9: 3208 | M9: 4
A10: 9 | B10: WorldWide Electric | C10: 2800 | D10: 280 | E10: 6200 | F10: 10 | G10: 118.7 | H10: 56.8 | I10: 28.1 | J10: 10.4 | K10: 23.4 | L10: 227400 | M10: 0
A11: 10 | B11: RED Global | C11: 2800 | D11: 280 | E11: 6200 | F11: 10 | G11: 116.8 | H11: 69.3 | I11: 30.7 | J11: 5.5 | K11: 11.3 | L11: 4441 | M11: 1
A12: 11 | B12: Impetus Wellness | C12: 180 | D12: 18 | E12: 850 | F12: 10 | G12: 115.2 | H12: 45.1 | I12: 51.4 | J12: 6.8 | K12: 11.9 | L12: 6867 | M12: 4
A13: 12 | B13: Nations Roof | C13: 0 | D13: 0 | E13: 0 | F13: 10 | G13: 114.9 | H13: 59.2 | I13: 27.9 | J13: 11.3 | K13: 16.5 | L13: 24691 | M13: 1
... A35: 34 | B35: Spectrum Control | C35: 180 | D35: 18 | E35: 850 | F35: 10 | G35: 49.8 | H35: 16.6 | I35: 15.3 | J35: 15.2 | K35: 2.7 | L35: 54400 | M35: 2
A36: 35 | B36: Cimsense | C36: NaN | D36: NaN | E36: 450 | F36: 10 | G36: 47.5 | H36: 21.1 | I36: 14.4 | J36: 2.3 | K36: 7.5 | L36: 3045 | M36: 0
A37: 36 | B37: Traeger Pellet Grills | C37: 600 | D37: 60 | E37: 800 | F37: 10 | G37: 46.53 | H37: 13.5 | I37: 19.9 | J37: 1.58 | K37: 11.55 | L37: 111 | M37: 3
A38: 37 | B38: Visual Comfort | C38: 800 | D38: 80 | E38: 2000 | F38: 10 | G38: 45.3 | H38: 17.3 | I38: 6.8 | J38: 2.2 | K38: 18.3 | L38: 11830 | M38: 0
A39: 38 | B39: Singer Industrial | C39: 847 | D39: 84.7 | E39: 0 | F39: 10 | G39: 42.7 | H39: 16.5 | I39: 13.4 | J39: 3.8 | K39: 9 | L39: 3405 | M39: 2
A40: 39 | B40: Excelitas Technologies | C40: 900 | D40: 90 | E40: 6500 | F40: 10 | G40: 40.4 | H40: 15.2 | I40: 10 | J40: 10.5 | K40: 4.7 | L40: 8624 | M40: 5
A41: 40 | B41: Huge | C41: 300 | D41: 30 | E41: 0 | F41: 10 | G41: 39.2 | H41: 26.2 | I41: 3.8 | J41: 5.1 | K41: 4.1 | L41: 26308 | M41: 0
A42: 41 | B42: Verdesian Life Sciences | C42: 450 | D42: 45 | E42: 850 | F42: 10 | G42: 39.1 | H42: 16.1 | I42: 8.9 | J42: 5.8 | K42: 8.2 | L42: 42117 | M42: 3
A43: 42 | B43: P&B Intermodal | C43: 380 | D43: 38 | E43: 850 | F43: 10 | G43: 37 | H43: 11.9 | I43: 19.2 | J43: 0.2 | K43: 5.6 | L43: 7120 | M43: 2
A44: 43 | B44: AS Software | C44: 127 | D44: 12.7 | E44: 890 | F44: 10 | G44: 35 | H44: 12.2 | I44: 17.7 | J44: 4.7 | K44: 1.2 | L44: 11800 | M44: 4
A45: 44 | B45: 50 Floor | C45: 180 | D45: 18 | E45: 0 | F45: 10 | G45: 34.4 | H45: 13.6 | I45: 14.2 | J45: 2.8 | K45: 3.8 | L45: 38600 | M45: 1
A46: 45 | B46: Hero Digital | C46: 45 | D46: 4.5 | E46: 280 | F46: 10 | G46: 33.7 | H46: 19.8 | I46: 7.5 | J46: 3.8 | K46: 3.3 | L46: 2300 | M46: 0
A47: 46 | B47: ROI CX Solutions | C47: 47 | D47: 4.7 | E47: 285 | F47: 10 | G47: 27.3 | H47: 13.2 | I47: 10.2 | J47: 2.9 | K47: 1 | L47: 88400 | M47: 1
A48: 47 | B48: Veseris | C48: 850 | D48: 85 | E48: 1400 | F48: 10 | G48: 24.7 | H48: 5.3 | I48: 10.6 | J48: 3.1 | K48: 5.6 | L48: 28073 | M48: 0
... A51: 50 | B51: TileBar | C51: 85 | D51: 8.5 | E51: 0 | F51: 10 | G51: 20.4 | H51: 7.6 | I51: 9.4 | J51: 1.1 | K51: 2.3 | L51: 13300 | M51: 1
A52: 51 | B52: Commonwealth Pain | C52: NaN | D52: NaN | E52: 0 | F52: 10 | G52: 14.7 | H52: 5.9 | I52: 4.1 | J52: 1.3 | K52: 3.4 | L52: 3519 | M52: 2
A53: 52 | B53: Meritus Gas Partners | C53: 340 | D53: 34 | E53: 520 | F53: 10 | G53: 13.9 | H53: 6 | I53: 0.3 | J53: 3.6 | K53: 4 | L53: 29500 | M53: 2
A54: 53 | B54: American Expediting | C54: 28 | D54: 2.8 | E54: 45 | F54: 10 | G54: 4.1 | H54: 0.6 | I54: 3.1 | J54: 0.2 | K54: 0.2 | L54: 2874 | M54: 1
A55: 54 | B55: American Oncology Network | C55: NaN | D55: NaN | E55: 0 | F55: 10 | G55: 0.0001134 | H55: 4.09e-05 | I55: 3.77e-05 | J55: 7.7e-06 | K55: 2.71e-05 | L55: 272 | M55: 1

Sheet 3. Use Cases Catalog
A1: Company | B1: Use Case ID | C1: Use Case Name | D1: Function | E1: Sub-Function | F1: AI Primitives | G1: Priority Tier | H1: Recommended Phase | I1: Cost Benefit ($M) | J1: Revenue Benefit ($M) | K1: Risk Benefit ($M) | L1: Cash Flow Benefit ($M) | M1: Total Annual Value ($M) | N1: Probability of Success | O1: Time-to-Value (mo) | P1: Effort Score | Q1: Data Readiness | R1: Integration Complexity | S1: Monthly Tokens (K) | T1: Annual Token Cost ($K) | U1: Cost Formula | V1: Revenue Formula | W1: Risk Formula | X1: Cash Flow Formula | Y1: Human Checkpoint | Z1: Adjusted Cost ($M) | AA1: Adjusted Revenue ($M) | AB1: Adjusted Risk ($M) | AC1: Adjusted Cash Flow ($M) | AD1: Total Adjusted Impact ($M) | AE1: Risk-Weighted Value ($M)
A2: 50 Floor | B2: UC-02 | C2: AI-Powered Customer Service Assistant | D2: Customer Service | E2: Inquiry Resolution | F2: Conversational Interfaces, Research & Information Retrieval | G2: High | H2: Q1 | I2: 4.1e-06 | J2: 0 | K2: 0 | L2: 0 | M2: 4.1e-06 | N2: 0.85 | O2: 6 | P2: 3 | Q2: 4 | R2: 3 | S2: 23400 | T2: 351 | U2: 43,200 hours × $85/hour × 60% deflection × 0.90 × 0.75 = $2.5M rounded down | V2: No direct revenue impact | W2: No direct risk impact | X2: No direct cash flow impact | Y2: Customer service representatives handle all escalated inquiries and approve any schedule changes or | Z2: =I2*'Dynamic Analysis Dashboard'!$B$8*'Dynamic Analysis Dashboard'!$B$9*'Dynamic Analysis Dashboard'!$B$21 -> 2.7675e-06 | AA2: =J2*'Dynamic Analysis Dashboard'!$B$8*'Dynamic Analysis Dashboard'!$B$9*'Dynamic Analysis Dashboard'!$B$21 -> 0 | AB2: =K2*'Dynamic Analysis Dashboard'!$B$10*'Dynamic Analysis Dashboard'!$B$9*'Dynamic Analysis Dashboard'!$B$21 -> 0 | AC2: =L2*'Dynamic Analysis Dashboard'!$B$11*'Dynamic Analysis Dashboard'!$B$9*'Dynamic Analysis Dashboard'!$B$21 -> 0 | AD2: =SUM(Z2:AC2) -> 2.7675e-06 | AE2: =AD2*N2 -> 2.352375e-06
A3: 50 Floor | B3: UC-04 | C3: Automated Lead Nurture Orchestration | D3: Sales Operations | E3: Lead Nurture | F3: Workflow Automation, Content Creation, Conversational Interfaces | G3: High | H3: Q2 | I3: 0.8 | J3: 8.5e-06 | K3: 0 | L3: 0 | M3: 9.3e-06 | N3: 0.7 | O3: 9 | P3: 4 | Q3: 3 | R3: 4 | S3: 11040 | T3: 189 | U3: 15 reps × 1,500 hours × $125/hour × 0.90 × 0.75 = $1.9M × 50% capacity = $900K rounded down | V3: 45,000 appointments × 32% non-close × 25% recovery × $4,800 × 0.95 × 0.75 = $12.3M rounded down | W3: No direct risk impact | X3: No direct cash flow impact | Y3: Sales representatives approve messaging templates and handle all direct phone conversations with re- | Z3: =I3*'Dynamic Analysis Dashboard'!$B$8*'Dynamic Analysis Dashboard'!$B$9*'Dynamic Analysis Dashboard'!$B$21 -> 0.54 | AA3: =J3*'Dynamic Analysis Dashboard'!$B$8*'Dynamic Analysis Dashboard'!$B$9*'Dynamic Analysis Dashboard'!$B$21 -> 5.7375e-06 | AB3: =K3*'Dynamic Analysis Dashboard'!$B$10*'Dynamic Analysis Dashboard'!$B$9*'Dynamic Analysis Dashboard'!$B$21 -> 0 | AC3: =L3*'Dynamic Analysis Dashboard'!$B$11*'Dynamic Analysis Dashboard'!$B$9*'Dynamic Analysis Dashboard'!$B$21 -> 0 | AD3: =SUM(Z3:AC3) -> 0.54000574 | AE3: =AD3*N3 -> 0.37800402
A4: 50 Floor | B4: UC-01 | C4: Intelligent Measurement Validation System | D4: Installation Coordination | E4: Measurement Validation | F4: Data Analysis, Workflow Automation | G4: Medium | H4: Q2 | I4: 5.2e-06 | J4: 0 | K4: 0.9 | L4: 0 | M4: 6.1e-06 | N4: 0.8 | O4: 9 | P4: 4 | Q4: 3 | R4: 4 | S4: 12375 | T4: 185 | U4: 13,500 hours × $125/hour × 0.90 × 0.75 = $1.1M labor + $3.5M waste × 60% reduction × 0.90 × 0.75 = $ | V4: No direct revenue impact | W4: $2.1M rework cost × 45% reduction × 0.80 × 0.75 = $500K rounded down | X4: No direct cash flow impact | Y4: Regional manager reviews all measurements flagged for >3% discrepancy before material procurement au | Z4: =I4*'Dynamic Analysis Dashboard'!$B$8*'Dynamic Analysis Dashboard'!$B$9*'Dynamic Analysis Dashboard'!$B$21 -> 3.51e-06 | AA4: =J4*'Dynamic Analysis Dashboard'!$B$8*'Dynamic Analysis Dashboard'!$B$9*'Dynamic Analysis Dashboard'!$B$21 -> 0 | AB4: =K4*'Dynamic Analysis Dashboard'!$B$10*'Dynamic Analysis Dashboard'!$B$9*'Dynamic Analysis Dashboard'!$B$21 -> 0.54 | AC4: =L4*'Dynamic Analysis Dashboard'!$B$11*'Dynamic Analysis Dashboard'!$B$9*'Dynamic Analysis Dashboard'!$B$21 -> 0 | AD4: =SUM(Z4:AC4) -> 0.54000351 | AE4: =AD4*N4 -> 0.43200281
A5: 50 Floor | B5: UC-03 | C5: Dynamic Sales Proposal Generator | D5: Sales Operations | E5: Proposal Generation | F5: Content Creation, Workflow Automation | G5: Critical | H5: Q1 | I5: 1.6e-06 | J5: 5.7e-06 | K5: 0 | L5: 0 | M5: 7.3e-06 | N5: 0.75 | O5: 6 | P5: 3 | Q5: 3 | R5: 3 | S5: 11250 | T5: 236 | U5: 300 reps × 200 hours × $125/hour × 0.90 × 0.75 = $5M × 25% time savings = $1.2M rounded down | V5: 45,000 appointments × 25 min saved × $125/hour × 0.95 × 0.75 = $1M + 45,000 appointments × 3% lift × | W5: No direct risk impact | X5: No direct cash flow impact | Y5: Sales representatives review all AI-generated proposals and adjust pricing or product recommendation | Z5: =I5*'Dynamic Analysis Dashboard'!$B$8*'Dynamic Analysis Dashboard'!$B$9*'Dynamic Analysis Dashboard'!$B$21 -> 1.08e-06 | AA5: =J5*'Dynamic Analysis Dashboard'!$B$8*'Dynamic Analysis Dashboard'!$B$9*'Dynamic Analysis Dashboard'!$B$21 -> 3.8475e-06 | AB5: =K5*'Dynamic Analysis Dashboard'!$B$10*'Dynamic Analysis Dashboard'!$B$9*'Dynamic Analysis Dashboard'!$B$21 -> 0 | AC5: =L5*'Dynamic Analysis Dashboard'!$B$11*'Dynamic Analysis Dashboard'!$B$9*'Dynamic Analysis Dashboard'!$B$21 -> 0 | AD5: =SUM(Z5:AC5) -> 4.9275e-06 | AE5: =AD5*N5 -> 3.695625e-06
A6: 50 Floor | B6: UC-05 | C6: Supplier Communication Automation Hub | D6: Procurement | E6: Supplier Communication | F6: Workflow Automation, Content Creation | G6: Medium | H6: Q3 | I6: 0.9 | J6: 0 | K6: 0 | L6: 1.7e-06 | M6: 2.6e-06 | N6: 0.75 | O6: 12 | P6: 4 | Q6: 2 | R6: 4 | S6: 2700 | T6: 46 | U6: $1.4M friction cost × 75% automation × 0.90 × 0.75 = $700K rounded down | V6: No direct revenue impact | W6: No direct risk impact | X6: 5 days × $350K daily revenue × 0.85 × 0.75 = $1.1M rounded down | Y6: Procurement specialists approve all purchase order changes exceeding $5,000 and handle supplier rela | Z6: =I6*'Dynamic Analysis Dashboard'!$B$8*'Dynamic Analysis Dashboard'!$B$9*'Dynamic Analysis Dashboard'!$B$21 -> 0.6075 | AA6: =J6*'Dynamic Analysis Dashboard'!$B$8*'Dynamic Analysis Dashboard'!$B$9*'Dynamic Analysis Dashboard'!$B$21 -> 0 | AB6: =K6*'Dynamic Analysis Dashboard'!$B$10*'Dynamic Analysis Dashboard'!$B$9*'Dynamic Analysis Dashboard'!$B$21 -> 0 | AC6: =L6*'Dynamic Analysis Dashboard'!$B$11*'Dynamic Analysis Dashboard'!$B$9*'Dynamic Analysis Dashboard'!$B$21 -> 1.08375e-06 | AD6: =SUM(Z6:AC6) -> 0.60750108 | AE6: =AD6*N6 -> 0.45562581
A7: 50 Floor | B7: UC-06 | C7: Intelligent Invoice Processing System | D7: Finance | E7: Accounts Payable | F7: Data Analysis, Workflow Automation | G7: Medium | H7: Q2 | I7: 0.6 | J7: 0 | K7: 0.2 | L7: 1.5e-06 | M7: 2.3e-06 | N7: 0.8 | O7: 6 | P7: 3 | Q7: 3 | R7: 3 | S7: 5280 | T7: 84 | U7: $890K friction cost × 80% automation × 0.90 × 0.75 = $400K rounded down | V7: No direct revenue impact | W7: $500K duplicate payment exposure × 50% reduction × 0.80 × 0.75 = $100K rounded down | X7: 6 days × $350K daily cash × 0.85 × 0.75 = $1.3M rounded down | Y7: Accounts payable specialists review all invoices with discrepancies and approve payments exceeding $ | Z7: =I7*'Dynamic Analysis Dashboard'!$B$8*'Dynamic Analysis Dashboard'!$B$9*'Dynamic Analysis Dashboard'!$B$21 -> 0.405 | AA7: =J7*'Dynamic Analysis Dashboard'!$B$8*'Dynamic Analysis Dashboard'!$B$9*'Dynamic Analysis Dashboard'!$B$21 -> 0 | AB7: =K7*'Dynamic Analysis Dashboard'!$B$10*'Dynamic Analysis Dashboard'!$B$9*'Dynamic Analysis Dashboard'!$B$21 -> 0.12 | AC7: =L7*'Dynamic Analysis Dashboard'!$B$11*'Dynamic Analysis Dashboard'!$B$9*'Dynamic Analysis Dashboard'!$B$21 -> 9.5625e-07 | AD7: =SUM(Z7:AC7) -> 0.52500096 | AE7: =AD7*N7 -> 0.42000076
A8: 50 Floor | B8: UC-07 | C8: Predictive Installation Quality Validator | D8: Quality Assurance | E8: Installation Review | F8: Data Analysis, Workflow Automation | G8: Medium | H8: Q3 | I8: 0 | J8: 0 | K8: 1.2e-06 | L8: 0 | M8: 1.2e-06 | N8: 0.75 | O8: 9 | P8: 3 | Q8: 3 | R8: 3 | S8: 6750 | T8: 106 | U8: No direct cost reduction beyond risk mitigation | V8: No direct revenue impact | W8: $2.1M rework cost × 75% prevention × 0.80 × 0.75 = $900K rounded down | X8: No direct cash flow impact | Y8: Quality managers conduct enhanced pre-installation reviews on all AI-flagged high-risk jobs before m | Z8: =I8*'Dynamic Analysis Dashboard'!$B$8*'Dynamic Analysis Dashboard'!$B$9*'Dynamic Analysis Dashboard'!$B$21 -> 0 | AA8: =J8*'Dynamic Analysis Dashboard'!$B$8*'Dynamic Analysis Dashboard'!$B$9*'Dynamic Analysis Dashboard'!$B$21 -> 0 | AB8: =K8*'Dynamic Analysis Dashboard'!$B$10*'Dynamic Analysis Dashboard'!$B$9*'Dynamic Analysis Dashboard'!$B$21 -> 7.2e-07 | AC8: =L8*'Dynamic Analysis Dashboard'!$B$11*'Dynamic Analysis Dashboard'!$B$9*'Dynamic Analysis Dashboard'!$B$21 -> 0 | AD8: =SUM(Z8:AC8) -> 7.2e-07 | AE8: =AD8*N8 -> 5.4e-07
A9: 50 Floor | B9: UC-08 | C9: Product Content Generation Engine | D9: Marketing | E9: Content Creation | F9: Content Creation, Research & Information Retrieval | G9: Medium | H9: Q1 | I9: 0.2 | J9: 0 | K9: 0 | L9: 0 | M9: 0.2 | N9: 0.85 | O9: 4 | P9: 2 | Q9: 4 | R9: 2 | S9: 600 | T9: 13 | U9: 3,600 hours × $100/hour × 75% time savings × 0.90 × 0.75 = $182K rounded down | V9: No direct revenue impact | W9: No direct risk impact | X9: No direct cash flow impact | Y9: Marketing specialists review and approve all AI-generated product content before publication | Z9: =I9*'Dynamic Analysis Dashboard'!$B$8*'Dynamic Analysis Dashboard'!$B$9*'Dynamic Analysis Dashboard'!$B$21 -> 0.135 | AA9: =J9*'Dynamic Analysis Dashboard'!$B$8*'Dynamic Analysis Dashboard'!$B$9*'Dynamic Analysis Dashboard'!$B$21 -> 0 | AB9: =K9*'Dynamic Analysis Dashboard'!$B$10*'Dynamic Analysis Dashboard'!$B$9*'Dynamic Analysis Dashboard'!$B$21 -> 0 | AC9: =L9*'Dynamic Analysis Dashboard'!$B$11*'Dynamic Analysis Dashboard'!$B$9*'Dynamic Analysis Dashboard'!$B$21 -> 0 | AD9: =SUM(Z9:AC9) -> 0.135 | AE9: =AD9*N9 -> 0.11475
A10: 50 Floor | B10: UC-09 | C10: Installer Training Content Generator | D10: Human Resources | E10: Training Development | F10: Content Creation, Coding Assistance | G10: Medium | H10: Q2 | I10: 0.06 | J10: 0 | K10: 0.1 | L10: 0 | M10: 0.16 | N10: 0.8 | O10: 4 | P10: 2 | Q10: 4 | R10: 2 | S10: 200 | T10: 5 | U10: 720 hours × $125/hour × 75% time savings × 0.90 × 0.75 = $54K rounded down | V10: No direct revenue impact | W10: $300K training gap exposure × 40% reduction × 0.80 × 0.75 = $72K rounded down | X10: No direct cash flow impact | Y10: HR training specialists review all generated content and validate technical accuracy before deployme | Z10: =I10*'Dynamic Analysis Dashboard'!$B$8*'Dynamic Analysis Dashboard'!$B$9*'Dynamic Analysis Dashboard'!$B$21 -> 0.0405 | AA10: =J10*'Dynamic Analysis Dashboard'!$B$8*'Dynamic Analysis Dashboard'!$B$9*'Dynamic Analysis Dashboard'!$B$21 -> 0 | AB10: =K10*'Dynamic Analysis Dashboard'!$B$10*'Dynamic Analysis Dashboard'!$B$9*'Dynamic Analysis Dashboard'!$B$21 -> 0.06 | AC10: =L10*'Dynamic Analysis Dashboard'!$B$11*'Dynamic Analysis Dashboard'!$B$9*'Dynamic Analysis Dashboard'!$B$21 -> 0 | AD10: =SUM(Z10:AC10) -> 0.1005 | AE10: =AD10*N10 -> 0.0804
A11: 50 Floor | B11: UC-10 | C11: Contract Review Acceleration System | D11: Legal | E11: Contract Management | F11: Research & Information Retrieval, Data Analysis, Content Creation | G11: Medium | H11: Q3 | I11: 0.2 | J11: 0 | K11: 0.3 | L11: 0.6 | M11: 1.1e-06 | N11: 0.75 | O11: 6 | P11: 3 | Q11: 3 | R11: 3 | S11: 900 | T11: 16 | U11: $340K friction cost × 70% time reduction × 0.90 × 0.75 = $161K rounded down | V11: No direct revenue impact | W11: $800K compliance exposure × 50% reduction × 0.80 × 0.75 = $240K rounded down | X11: 4 days × $350K daily cash × 0.85 × 0.75 × 50% contracts = $446K rounded down | Y11: Legal counsel reviews all AI-flagged contract provisions and approves final agreement terms before e | Z11: =I11*'Dynamic Analysis Dashboard'!$B$8*'Dynamic Analysis Dashboard'!$B$9*'Dynamic Analysis Dashboard'!$B$21 -> 0.135 | AA11: =J11*'Dynamic Analysis Dashboard'!$B$8*'Dynamic Analysis Dashboard'!$B$9*'Dynamic Analysis Dashboard'!$B$21 -> 0 | AB11: =K11*'Dynamic Analysis Dashboard'!$B$10*'Dynamic Analysis Dashboard'!$B$9*'Dynamic Analysis Dashboard'!$B$21 -> 0.18 | AC11: =L11*'Dynamic Analysis Dashboard'!$B$11*'Dynamic Analysis Dashboard'!$B$9*'Dynamic Analysis Dashboard'!$B$21 -> 0.3825 | AD11: =SUM(Z11:AC11) -> 0.6975 | AE11: =AD11*N11 -> 0.523125
A12: American Dental | B12: UC-03 | C12: Predictive Patient Engagement & No-Show Prevention | D12: Patient Services | E12: Appointment Scheduling | F12: Data Analysis, Conversational Interfaces, Workflow Automation | G12: High | H12: Q2 2026 | I12: 2.4e-06 | J12: 1.18e-05 | K12: 0 | L12: 0 | M12: 1.42e-05 | N12: 0.85 | O12: 7 | P12: 3 | Q12: 3 | R12: 3 | S12: 259200 | T12: 0.0397 | U12: 8,400 hours deflected from manual confirmation calls × $50/hour admin rate × 0.90 × 0.75 = $2.4M | V12: 11 percentage point no-show reduction × 180 practices × 12,000 visits × $285 average revenue × 0.95 | W12: Not applicable - no direct risk reduction | X12: Not applicable - no direct cash flow impact | Y12: Front desk staff reviews AI-flagged high-risk appointments each morning and makes personal confirmat | Z12: =I12*'Dynamic Analysis Dashboard'!$B$8*'Dynamic Analysis Dashboard'!$B$9*'Dynamic Analysis Dashboard'!$B$21 -> 1.62e-06 | AA12: =J12*'Dynamic Analysis Dashboard'!$B$8*'Dynamic Analysis Dashboard'!$B$9*'Dynamic Analysis Dashboard'!$B$21 -> 7.965e-06 | AB12: =K12*'Dynamic Analysis Dashboard'!$B$10*'Dynamic Analysis Dashboard'!$B$9*'Dynamic Analysis Dashboard'!$B$21 -> 0 | AC12: =L12*'Dynamic Analysis Dashboard'!$B$11*'Dynamic Analysis Dashboard'!$B$9*'Dynamic Analysis Dashboard'!$B$21 -> 0 | AD12: =SUM(Z12:AC12) -> 9.585e-06 | AE12: =AD12*N12 -> 8.14725e-06
A13: American Dental | B13: UC-05 | C13: Intelligent Patient Inquiry Router & Response System | D13: Patient Services | E13: Patient Communication | F13: Conversational Interfaces, Research & Information Retrieval, Workflow Automation | G13: High | H13: Q1 2026 | I13: 3.6e-06 | J13: 8.1e-06 | K13: 0 | L13: 0 | M13: 1.17e-05 | N13: 0.8 | O13: 6 | P13: 2 | Q13: 3 | R13: 3 | S13: 25920 | T13: 0.0065 | U13: 22,000 hours deflected from manual inquiry handling × $100/hour patient services rate × 0.90 × 0.75 | V13: 14 percentage point conversion improvement × 180 practices × 1,200 monthly inquiries × 12 months × $ | W13: Not applicable - no direct risk reduction | X13: Not applicable - no direct cash flow impact | Y13: Patient services supervisor reviews all AI-scheduled new patient appointments within 4 hours to veri | Z13: =I13*'Dynamic Analysis Dashboard'!$B$8*'Dynamic Analysis Dashboard'!$B$9*'Dynamic Analysis Dashboard'!$B$21 -> 2.43e-06 | AA13: =J13*'Dynamic Analysis Dashboard'!$B$8*'Dynamic Analysis Dashboard'!$B$9*'Dynamic Analysis Dashboard'!$B$21 -> 5.4675e-06 | AB13: =K13*'Dynamic Analysis Dashboard'!$B$10*'Dynamic Analysis Dashboard'!$B$9*'Dynamic Analysis Dashboard'!$B$21 -> 0 | AC13: =L13*'Dynamic Analysis Dashboard'!$B$11*'Dynamic Analysis Dashboard'!$B$9*'Dynamic Analysis Dashboard'!$B$21 -> 0 | AD13: =SUM(Z13:AC13) -> 7.8975e-06 | AE13: =AD13*N13 -> 6.318e-06
... A187: EZ Texting | B187: UC-02 | C187: Proactive Campaign Performance Advisor | D187: Customer Success | E187: Account Management | F187: Data Analysis, Content Creation | G187: Critical | H187: Q1 | I187: 3.4e-06 | J187: 5.7e-06 | K187: 0 | L187: 0 | M187: 9.1e-06 | N187: 0.75 | O187: 5 | P187: 2 | Q187: 4 | R187: 2 | S187: 32500 | T187: 6.9 | U187: 11,250 deflected QBR hours × $150/hour × 0.90 × 0.75 = $3.4M | V187: 7% retention rate improvement × $45M revenue × 0.95 × 0.75 = $5.7M | W187: N/A | X187: N/A | Y187: Customer Success Manager validates performance insights and recommendation priorities before custome | Z187: =I187*'Dynamic Analysis Dashboard'!$B$8*'Dynamic Analysis Dashboard'!$B$9*'Dynamic Analysis Dashboard'!$B$21 -> 2.295e-06 | AA187: =J187*'Dynamic Analysis Dashboard'!$B$8*'Dynamic Analysis Dashboard'!$B$9*'Dynamic Analysis Dashboard'!$B$21 -> 3.8475e-06 | AB187: =K187*'Dynamic Analysis Dashboard'!$B$10*'Dynamic Analysis Dashboard'!$B$9*'Dynamic Analysis Dashboard'!$B$21 -> 0 | AC187: =L187*'Dynamic Analysis Dashboard'!$B$11*'Dynamic Analysis Dashboard'!$B$9*'Dynamic Analysis Dashboard'!$B$21 -> 0 | AD187: =SUM(Z187:AC187) -> 6.1425e-06 | AE187: =AD187*N187 -> 4.606875e-06
A188: EZ Texting | B188: UC-03 | C188: Carrier Compliance Intelligence Platform | D188: Product Management | E188: Compliance | G188: Medium | H188: Q3 | I188: 2.7e-06 | J188: 0 | K188: 1.6e-06 | L188: 0 | M188: 4.3e-06 | N188: 0.7 | O188: 9 | P188: 4 | Q188: 2 | R188: 4 | S188: 5610 | T188: 1.2 | U188: 14,500 deflected compliance monitoring hours × $185/hour × 0.90 × 0.75 = $2.7M | V188: N/A | W188: 75% reduction × $180K annual penalties × 12-year horizon × 0.80 × 0.75 = $1.6M | X188: N/A | Y188: Product Manager reviews AI-generated impact assessment and feature recommendations before roadmap pr | Z188: =I188*'Dynamic Analysis Dashboard'!$B$8*'Dynamic Analysis Dashboard'!$B$9*'Dynamic Analysis Dashboard'!$B$21 -> 1.8225e-06 | AA188: =J188*'Dynamic Analysis Dashboard'!$B$8*'Dynamic Analysis Dashboard'!$B$9*'Dynamic Analysis Dashboard'!$B$21 -> 0 | AB188: =K188*'Dynamic Analysis Dashboard'!$B$10*'Dynamic Analysis Dashboard'!$B$9*'Dynamic Analysis Dashboard'!$B$21 -> 9.6e-07 | AC188: =L188*'Dynamic Analysis Dashboard'!$B$11*'Dynamic Analysis Dashboard'!$B$9*'Dynamic Analysis Dashboard'!$B$21 -> 0 | AD188: =SUM(Z188:AC188) -> 2.7825e-06 | AE188: =AD188*N188 -> 1.94775e-06
A189: EZ Texting | B189: UC-05 | C189: Intelligent Sales Research Assistant | D189: Sales | E189: Lead Qualification | F189: Research & Information Retrieval, Data Analysis, Content Creation | G189: Critical | H189: Q1 | I189: 1.9e-06 | J189: 6.8e-06 | K189: 0 | L189: 0 | M189: 8.7e-06 | N189: 0.75 | O189: 6 | P189: 3 | Q189: 2 | R189: 3 | S189: 9240 | T189: 2 | U189: 7,200 deflected research hours × $150/hour × 0.90 × 0.75 = $1.9M | V189: 9% conversion rate improvement × 18% baseline conversion × $45M revenue × 1.35 growth multiplier × 0 | W189: N/A | X189: N/A | Y189: Sales representative reviews AI-generated prospect profile and validates recommended use cases again | Z189: =I189*'Dynamic Analysis Dashboard'!$B$8*'Dynamic Analysis Dashboard'!$B$9*'Dynamic Analysis Dashboard'!$B$21 -> 1.2825e-06 | AA189: =J189*'Dynamic Analysis Dashboard'!$B$8*'Dynamic Analysis Dashboard'!$B$9*'Dynamic Analysis Dashboard'!$B$21 -> 4.59e-06 | AB189: =K189*'Dynamic Analysis Dashboard'!$B$10*'Dynamic Analysis Dashboard'!$B$9*'Dynamic Analysis Dashboard'!$B$21 -> 0 | AC189: =L189*'Dynamic Analysis Dashboard'!$B$11*'Dynamic Analysis Dashboard'!$B$9*'Dynamic Analysis Dashboard'!$B$21 -> 0 | AD189: =SUM(Z189:AC189) -> 5.8725e-06 | AE189: =AD189*N189 -> 4.404375e-06
A190: EZ Texting | B190: UC-08 | C190: Automated Knowledge Base Maintenance | D190: Customer Support | E190: Documentation | F190: Data Analysis, Content Creation | G190: Medium | H190: Q4 | I190: 0.8 | J190: 0 | K190: 0.9 | L190: 0 | M190: 1.7e-06 | N190: 0.75 | O190: 4 | P190: 2 | Q190: 4 | R190: 2 | S190: 2320 | T190: 0.5 | U190: 3,600 deflected documentation hours × $125/hour × 0.90 × 0.75 = $800K | V190: N/A | W190: 40% reduction × $200K annual customer confusion cost × 8-year horizon × 0.80 × 0.75 = $900K | X190: N/A | Y190: Technical writer reviews AI-generated article updates for technical accuracy and brand voice consist | Z190: =I190*'Dynamic Analysis Dashboard'!$B$8*'Dynamic Analysis Dashboard'!$B$9*'Dynamic Analysis Dashboard'!$B$21 -> 0.54 | AA190: =J190*'Dynamic Analysis Dashboard'!$B$8*'Dynamic Analysis Dashboard'!$B$9*'Dynamic Analysis Dashboard'!$B$21 -> 0 | AB190: =K190*'Dynamic Analysis Dashboard'!$B$10*'Dynamic Analysis Dashboard'!$B$9*'Dynamic Analysis Dashboard'!$B$21 -> 0.54 | AC190: =L190*'Dynamic Analysis Dashboard'!$B$11*'Dynamic Analysis Dashboard'!$B$9*'Dynamic Analysis Dashboard'!$B$21 -> 0 | AD190: =SUM(Z190:AC190) -> 1.08 | AE190: =AD190*N190 -> 0.81
A191: EZ Texting | B191: UC-10 | C191: API Documentation Automation | D191: Engineering | E191: API Documentation | F191: Coding Assistance, Content Creation | G191: Medium | H191: Q4 | I191: 1.2e-06 | J191: 1.8e-06 | K191: 0 | L191: 0 | M191: 3e-06 | N191: 0.75 | O191: 5 | P191: 3 | Q191: 3 | R191: 3 | S191: 1440 | T191: 0.3 | U191: 4,200 deflected documentation hours × $185/hour × 0.90 × 0.75 = $1.2M | V191: 28% documentation coverage improvement × 5% developer adoption impact × $45M revenue × 1.35 growth m | W191: N/A | X191: N/A | Y191: Senior engineer reviews generated documentation for technical accuracy and validates code examples e | Z191: =I191*'Dynamic Analysis Dashboard'!$B$8*'Dynamic Analysis Dashboard'!$B$9*'Dynamic Analysis Dashboard'!$B$21 -> 8.1e-07 | AA191: =J191*'Dynamic Analysis Dashboard'!$B$8*'Dynamic Analysis Dashboard'!$B$9*'Dynamic Analysis Dashboard'!$B$21 -> 1.215e-06 | AB191: =K191*'Dynamic Analysis Dashboard'!$B$10*'Dynamic Analysis Dashboard'!$B$9*'Dynamic Analysis Dashboard'!$B$21 -> 0 | AC191: =L191*'Dynamic Analysis Dashboard'!$B$11*'Dynamic Analysis Dashboard'!$B$9*'Dynamic Analysis Dashboard'!$B$21 -> 0 | AD191: =SUM(Z191:AC191) -> 2.025e-06 | AE191: =AD191*N191 -> 1.51875e-06
A192: Hero Digital | B192: UC-01 | C192: Intelligent Proposal Assembly System | D192: Business Development | E192: Proposal Development | F192: Research & Information Retrieval, Content Creation, Workflow Automation | G192: High | H192: Q2 | I192: 3.5e-06 | J192: 1.9e-06 | K192: 0 | L192: 0.8 | M192: 6.2e-06 | N192: 0.8 | O192: 9 | P192: 4 | Q192: 3 | R192: 4 | S192: 3600 | T192: 2592 | U192: 14,200 hours × $185/hr × 0.90 × 0.75 = $1.8M proposal time + 8,400 hours × $285/hr × 0.90 × 0.75 = $ | V192: 120 incremental pursuits × $375K avg value × 6% win rate lift × 0.95 × 0.75 = $1.9M | W192: No material risk reduction | X192: 12 days acceleration × $123K daily revenue × 0.85 × 0.75 = $940K rounded to $800K | Y192: Senior strategist reviews and approves all AI-assembled proposal sections, customizes strategic posi | Z192: =I192*'Dynamic Analysis Dashboard'!$B$8*'Dynamic Analysis Dashboard'!$B$9*'Dynamic Analysis Dashboard'!$B$21 -> 2.3625e-06 | AA192: =J192*'Dynamic Analysis Dashboard'!$B$8*'Dynamic Analysis Dashboard'!$B$9*'Dynamic Analysis Dashboard'!$B$21 -> 1.2825e-06 | AB192: =K192*'Dynamic Analysis Dashboard'!$B$10*'Dynamic Analysis Dashboard'!$B$9*'Dynamic Analysis Dashboard'!$B$21 -> 0 | AC192: =L192*'Dynamic Analysis Dashboard'!$B$11*'Dynamic Analysis Dashboard'!$B$9*'Dynamic Analysis Dashboard'!$B$21 -> 0.51 | AD192: =SUM(Z192:AC192) -> 0.51000365 | AE192: =AD192*N192 -> 0.40800292
A193: Hero Digital | B193: UC-03 | C193: Adaptive Content Brief Generator | D193: Content Production | E193: Content Briefing | F193: Research & Information Retrieval, Content Creation | G193: High | H193: Q2 | I193: 1.8e-06 | J193: 0 | K193: 1.3e-06 | L193: 0 | M193: 3.1e-06 | N193: 0.75 | O193: 6 | P193: 3 | Q193: 3 | R193: 3 | S193: 3360 | T193: 2419.2 | U193: 18 hours × 280 projects × $185/hr × 0.90 × 0.75 = $1.7M rounded to $1.8M | V193: No direct revenue impact | W193: 28% reduction in rework × $6.2M annual rework cost × 0.80 × 0.75 = $1.3M | X193: No material cash flow impact | Y193: Content strategist reviews AI-generated brief for creative accuracy, validates brand guideline compl | Z193: =I193*'Dynamic Analysis Dashboard'!$B$8*'Dynamic Analysis Dashboard'!$B$9*'Dynamic Analysis Dashboard'!$B$21 -> 1.215e-06 | AA193: =J193*'Dynamic Analysis Dashboard'!$B$8*'Dynamic Analysis Dashboard'!$B$9*'Dynamic Analysis Dashboard'!$B$21 -> 0 | AB193: =K193*'Dynamic Analysis Dashboard'!$B$10*'Dynamic Analysis Dashboard'!$B$9*'Dynamic Analysis Dashboard'!$B$21 -> 7.8e-07 | AC193: =L193*'Dynamic Analysis Dashboard'!$B$11*'Dynamic Analysis Dashboard'!$B$9*'Dynamic Analysis Dashboard'!$B$21 -> 0 | AD193: =SUM(Z193:AC193) -> 1.995e-06 | AE193: =AD193*N193 -> 1.49625e-06
A194: Hero Digital | B194: UC-04 | C194: Multi-Stage Content Quality Assistant | D194: Content Production | E194: Quality Review | F194: Data Analysis, Content Creation | G194: High | H194: Q2 | I194: 2.4e-06 | J194: 0 | K194: 0.9 | L194: 0 | M194: 3.3e-06 | N194: 0.8 | O194: 7 | P194: 3 | Q194: 4 | R194: 3 | S194: 5040 | T194: 6048 | U194: 12 hours × 280 projects × $125/hr × 0.90 × 0.75 = $2.3M rounded to $2.4M | V194: No direct revenue impact | W194: 16% reduction in client dissatisfaction × $7.4M client retention risk × 0.80 × 0.75 = $890K rounded | X194: No material cash flow impact | Y194: Senior content reviewer validates AI quality findings, makes final judgment on creative execution an | Z194: =I194*'Dynamic Analysis Dashboard'!$B$8*'Dynamic Analysis Dashboard'!$B$9*'Dynamic Analysis Dashboard'!$B$21 -> 1.62e-06 | AA194: =J194*'Dynamic Analysis Dashboard'!$B$8*'Dynamic Analysis Dashboard'!$B$9*'Dynamic Analysis Dashboard'!$B$21 -> 0 | AB194: =K194*'Dynamic Analysis Dashboard'!$B$10*'Dynamic Analysis Dashboard'!$B$9*'Dynamic Analysis Dashboard'!$B$21 -> 0.54 | AC194: =L194*'Dynamic Analysis Dashboard'!$B$11*'Dynamic Analysis Dashboard'!$B$9*'Dynamic Analysis Dashboard'!$B$21 -> 0 | AD194: =SUM(Z194:AC194) -> 0.54000162 | AE194: =AD194*N194 -> 0.4320013
A195: Hero Digital | B195: UC-05 | C195: Intelligent Pitch Deck Composer | D195: Business Development | E195: Pitch Preparation | F195: Research & Information Retrieval, Content Creation, Data Analysis | G195: High | H195: Q1 | I195: 3.2e-06 | J195: 1.6e-06 | K195: 0 | L195: 0 | M195: 4.8e-06 | N195: 0.75 | O195: 6 | P195: 3 | Q195: 3 | R195: 3 | S195: 2880 | T195: 2073.6 | U195: 24 hours × 180 pitches × $285/hr × 0.90 × 0.75 = $3.1M rounded to $3.2M | V195: 90 incremental pitches × $375K avg value × 5% win rate lift × 0.95 × 0.75 = $1.5M rounded to $1.6M | W195: No material risk reduction | X195: No material cash flow impact | Y195: Business development director reviews AI-composed pitch deck, customizes strategic positioning based | Z195: =I195*'Dynamic Analysis Dashboard'!$B$8*'Dynamic Analysis Dashboard'!$B$9*'Dynamic Analysis Dashboard'!$B$21 -> 2.16e-06 | AA195: =J195*'Dynamic Analysis Dashboard'!$B$8*'Dynamic Analysis Dashboard'!$B$9*'Dynamic Analysis Dashboard'!$B$21 -> 1.08e-06 | AB195: =K195*'Dynamic Analysis Dashboard'!$B$10*'Dynamic Analysis Dashboard'!$B$9*'Dynamic Analysis Dashboard'!$B$21 -> 0 | AC195: =L195*'Dynamic Analysis Dashboard'!$B$11*'Dynamic Analysis Dashboard'!$B$9*'Dynamic Analysis Dashboard'!$B$21 -> 0 | AD195: =SUM(Z195:AC195) -> 3.24e-06 | AE195: =AD195*N195 -> 2.43e-06
A196: Hero Digital | B196: UC-07 | C196: Project Onboarding Packet Assembler | D196: Client Management | E196: Onboarding Documentation | F196: Research & Information Retrieval, Content Creation, Workflow Automation | G196: High | H196: Q1 | I196: 0.9 | J196: 0 | K196: 0 | L196: 1.4e-06 | M196: 2.3e-06 | N196: 0.8 | O196: 5 | P196: 2 | Q196: 4 | R196: 2 | S196: 1400 | T196: 1008 | U196: 8 hours × 140 projects × $125/hr × 0.90 × 0.75 = $850K rounded to $900K | V196: No direct revenue impact | W196: No material risk reduction | X196: 11 days × $123K daily revenue × 0.85 × 0.75 = $1.3M rounded to $1.4M | Y196: Account manager reviews AI-assembled onboarding packet, validates project-specific details, customiz | Z196: =I196*'Dynamic Analysis Dashboard'!$B$8*'Dynamic Analysis Dashboard'!$B$9*'Dynamic Analysis Dashboard'!$B$21 -> 0.6075 | AA196: =J196*'Dynamic Analysis Dashboard'!$B$8*'Dynamic Analysis Dashboard'!$B$9*'Dynamic Analysis Dashboard'!$B$21 -> 0 | AB196: =K196*'Dynamic Analysis Dashboard'!$B$10*'Dynamic Analysis Dashboard'!$B$9*'Dynamic Analysis Dashboard'!$B$21 -> 0 | AC196: =L196*'Dynamic Analysis Dashboard'!$B$11*'Dynamic Analysis Dashboard'!$B$9*'Dynamic Analysis Dashboard'!$B$21 -> 8.925e-07 | AD196: =SUM(Z196:AC196) -> 0.60750089 | AE196: =AD196*N196 -> 0.48600071
A197: Hero Digital | B197: UC-10 | C197: AI-Enhanced Invoice Narrative System | D197: Finance | E197: Invoicing Operations | F197: Research & Information Retrieval, Content Creation | G197: High | H197: Q1 | I197: 0.7 | J197: 0 | K197: 0 | L197: 1.1e-06 | M197: 1.8e-06 | N197: 0.8 | O197: 4 | P197: 2 | Q197: 4 | R197: 2 | S197: 9240 | T197: 6652.8 | U197: 2.5 hours × 140 clients × 12 months × $125/hr × 0.90 × 0.75 = $660K rounded to $700K | V197: No direct revenue impact | W197: No material risk reduction | X197: 7 days × $123K daily revenue × 0.85 × 0.75 = $1.0M rounded to $1.1M | Y197: Finance manager validates AI-generated invoice narratives against actual work performed, adjusts lan | Z197: =I197*'Dynamic Analysis Dashboard'!$B$8*'Dynamic Analysis Dashboard'!$B$9*'Dynamic Analysis Dashboard'!$B$21 -> 0.4725 | AA197: =J197*'Dynamic Analysis Dashboard'!$B$8*'Dynamic Analysis Dashboard'!$B$9*'Dynamic Analysis Dashboard'!$B$21 -> 0 | AB197: =K197*'Dynamic Analysis Dashboard'!$B$10*'Dynamic Analysis Dashboard'!$B$9*'Dynamic Analysis Dashboard'!$B$21 -> 0 | AC197: =L197*'Dynamic Analysis Dashboard'!$B$11*'Dynamic Analysis Dashboard'!$B$9*'Dynamic Analysis Dashboard'!$B$21 -> 7.0125e-07 | AD197: =SUM(Z197:AC197) -> 0.4725007 | AE197: =AD197*N197 -> 0.37800056
A198: Hero Digital | B198: UC-02 | C198: AI-Powered Research Synthesis Engine | D198: Strategy Consulting | E198: Market Research | G198: Medium | H198: Q3 | I198: 2.5e-06 | J198: 2.8e-06 | K198: 0 | L198: 0 | M198: 5.3e-06 | N198: 0.75 | O198: 12 | P198: 4 | Q198: 2 | R198: 4 | S198: 8400 | T198: 18144 | U198: 32 hours × 140 engagements × $285/hr × 0.90 × 0.75 = $2.4M rounded to $2.5M | V198: 32 hours saved × 140 engagements × $285/hr converted to billable × 0.95 × 0.75 = $900K + strategic d | W198: No material risk reduction | X198: No material cash flow impact | Y198: Strategy consultant validates all synthesized research findings, verifies source accuracy, adds indu | Z198: =I198*'Dynamic Analysis Dashboard'!$B$8*'Dynamic Analysis Dashboard'!$B$9*'Dynamic Analysis Dashboard'!$B$21 -> 1.6875e-06 | AA198: =J198*'Dynamic Analysis Dashboard'!$B$8*'Dynamic Analysis Dashboard'!$B$9*'Dynamic Analysis Dashboard'!$B$21 -> 1.89e-06 | AB198: =K198*'Dynamic Analysis Dashboard'!$B$10*'Dynamic Analysis Dashboard'!$B$9*'Dynamic Analysis Dashboard'!$B$21 -> 0 | AC198: =L198*'Dynamic Analysis Dashboard'!$B$11*'Dynamic Analysis Dashboard'!$B$9*'Dynamic Analysis Dashboard'!$B$21 -> 0 | AD198: =SUM(Z198:AC198) -> 3.5775e-06 | AE198: =AD198*N198 -> 2.683125e-06
A199: Hero Digital | B199: UC-06 | C199: Automated Competitive Intelligence Monitor | D199: Strategy Consulting | E199: Competitive Analysis | F199: Research & Information Retrieval, Data Analysis, Workflow Automation | G199: Medium | H199: Q4 | I199: 1.4e-06 | J199: 1.2e-06 | K199: 0 | L199: 0 | M199: 2.6e-06 | N199: 0.7 | O199: 10 | P199: 4 | Q199: 2 | R199: 4 | S199: 18480 | T199: 16934.4 | U199: 8 hours × 140 engagements × $185/hr × 0.90 × 0.75 = $1.3M rounded to $1.4M | V199: Competitive insights enabling 3% win rate lift × 45 pursuits/qtr × 4 qtrs × $375K avg × 0.95 × 0.75 | W199: No material risk reduction | X199: No material cash flow impact | Y199: Strategy consultant validates AI-identified competitive insights, assesses strategic significance fo | Z199: =I199*'Dynamic Analysis Dashboard'!$B$8*'Dynamic Analysis Dashboard'!$B$9*'Dynamic Analysis Dashboard'!$B$21 -> 9.45e-07 | AA199: =J199*'Dynamic Analysis Dashboard'!$B$8*'Dynamic Analysis Dashboard'!$B$9*'Dynamic Analysis Dashboard'!$B$21 -> 8.1e-07 | AB199: =K199*'Dynamic Analysis Dashboard'!$B$10*'Dynamic Analysis Dashboard'!$B$9*'Dynamic Analysis Dashboard'!$B$21 -> 0 | AC199: =L199*'Dynamic Analysis Dashboard'!$B$11*'Dynamic Analysis Dashboard'!$B$9*'Dynamic Analysis Dashboard'!$B$21 -> 0 | AD199: =SUM(Z199:AC199) -> 1.755e-06 | AE199: =AD199*N199 -> 1.2285e-06
A200: Hero Digital | B200: UC-08 | C200: Intelligent Status Report Generator | D200: Client Management | E200: Status Reporting | F200: Data Analysis, Content Creation, Workflow Automation | G200: Medium | H200: Q3 | I200: 1.6e-06 | J200: 0 | K200: 0.6 | L200: 0 | M200: 2.2e-06 | N200: 0.8 | O200: 6 | P200: 3 | Q200: 4 | R200: 3 | S200: 19600 | T200: 14112 | U200: 3 hours × 140 projects × 52 weeks × $125/hr × 0.90 × 0.75 = $1.5M rounded to $1.6M | V200: No direct revenue impact | W200: 12% improvement in client satisfaction × $6.8M retention risk × 0.80 × 0.75 = $650K rounded to $600K | X200: No material cash flow impact | Y200: Account manager validates AI-generated status narrative, adds strategic context for delays or risks, | Z200: =I200*'Dynamic Analysis Dashboard'!$B$8*'Dynamic Analysis Dashboard'!$B$9*'Dynamic Analysis Dashboard'!$B$21 -> 1.08e-06 | AA200: =J200*'Dynamic Analysis Dashboard'!$B$8*'Dynamic Analysis Dashboard'!$B$9*'Dynamic Analysis Dashboard'!$B$21 -> 0 | AB200: =K200*'Dynamic Analysis Dashboard'!$B$10*'Dynamic Analysis Dashboard'!$B$9*'Dynamic Analysis Dashboard'!$B$21 -> 0.36 | AC200: =L200*'Dynamic Analysis Dashboard'!$B$11*'Dynamic Analysis Dashboard'!$B$9*'Dynamic Analysis Dashboard'!$B$21 -> 0 | AD200: =SUM(Z200:AC200) -> 0.36000108 | AE200: =AD200*N200 -> 0.28800086
A201: Hero Digital | B201: UC-09 | C201: Semantic Knowledge Retrieval System | D201: Operations | E201: Knowledge Management | F201: Research & Information Retrieval, Data Analysis | G201: Medium | H201: Q4 | I201: 2.1e-06 | J201: 0 | K201: 0 | L201: 0 | M201: 2.1e-06 | N201: 0.85 | O201: 10 | P201: 4 | Q201: 2 | R201: 4 | S201: 49280 | T201: 35481.6 | U201: 12 minutes × 280 consultants × 220 workdays × $185/hr × 0.90 × 0.75 = $2.0M rounded to $2.1M | V201: No direct revenue impact | W201: No material risk reduction | X201: No material cash flow impact | Y201: Consultant validates relevance of AI-retrieved prior work for current engagement context, adapts reu | Z201: =I201*'Dynamic Analysis Dashboard'!$B$8*'Dynamic Analysis Dashboard'!$B$9*'Dynamic Analysis Dashboard'!$B$21 -> 1.4175e-06 | AA201: =J201*'Dynamic Analysis Dashboard'!$B$8*'Dynamic Analysis Dashboard'!$B$9*'Dynamic Analysis Dashboard'!$B$21 -> 0 | AB201: =K201*'Dynamic Analysis Dashboard'!$B$10*'Dynamic Analysis Dashboard'!$B$9*'Dynamic Analysis Dashboard'!$B$21 -> 0 | AC201: =L201*'Dynamic Analysis Dashboard'!$B$11*'Dynamic Analysis Dashboard'!$B$9*'Dynamic Analysis Dashboard'!$B$21 -> 0 | AD201: =SUM(Z201:AC201) -> 1.4175e-06 | AE201: =AD201*N201 -> 1.204875e-06
A202: Huge | B202: UC-01 | C202: Pitch Intelligence Assistant | D202: Business Development | E202: Pitch Preparation | F202: Research & Information Retrieval, Content Creation | G202: High | H202: Q1 | I202: 4.4e-06 | J202: 3.8e-06 | K202: 0 | L202: 0 | M202: 8.2e-06 | N202: 0.75 | O202: 9 | P202: 3 | Q202: 2 | R202: 3 | S202: 10260 | T202: 46.8 | U202: No cost impact | V202: 7% win rate lift × $190M annual pitch pipeline × 0.95 × 0.75 = $9.4M × 0.40 adoption = $3.8M | W202: N/A | X202: N/A | Y202: Strategy directors review and validate all market insights before inclusion in client-facing pitch m | Z202: =I202*'Dynamic Analysis Dashboard'!$B$8*'Dynamic Analysis Dashboard'!$B$9*'Dynamic Analysis Dashboard'!$B$21 -> 2.97e-06 | AA202: =J202*'Dynamic Analysis Dashboard'!$B$8*'Dynamic Analysis Dashboard'!$B$9*'Dynamic Analysis Dashboard'!$B$21 -> 2.565e-06 | AB202: =K202*'Dynamic Analysis Dashboard'!$B$10*'Dynamic Analysis Dashboard'!$B$9*'Dynamic Analysis Dashboard'!$B$21 -> 0 | AC202: =L202*'Dynamic Analysis Dashboard'!$B$11*'Dynamic Analysis Dashboard'!$B$9*'Dynamic Analysis Dashboard'!$B$21 -> 0 | AD202: =SUM(Z202:AC202) -> 5.535e-06 | AE202: =AD202*N202 -> 4.15125e-06
A203: Huge | B203: UC-06 | C203: Knowledge Discovery Engine | D203: Knowledge Management | E203: Case Study Retrieval | F203: Research & Information Retrieval, Conversational Interfaces | G203: High | H203: Q1 | I203: 2.2e-06 | J203: 0 | K203: 0 | L203: 0 | M203: 2.2e-06 | N203: 0.85 | O203: 6 | P203: 2 | Q203: 2 | R203: 2 | S203: 19740 | T203: 32.76 | U203: No cost impact | V203: N/A | W203: N/A | X203: N/A | Y203: Account strategists review retrieved case studies for relevance to current client context and approv | Z203: =I203*'Dynamic Analysis Dashboard'!$B$8*'Dynamic Analysis Dashboard'!$B$9*'Dynamic Analysis Dashboard'!$B$21 -> 1.485e-06 | AA203: =J203*'Dynamic Analysis Dashboard'!$B$8*'Dynamic Analysis Dashboard'!$B$9*'Dynamic Analysis Dashboard'!$B$21 -> 0 | AB203: =K203*'Dynamic Analysis Dashboard'!$B$10*'Dynamic Analysis Dashboard'!$B$9*'Dynamic Analysis Dashboard'!$B$21 -> 0 | AC203: =L203*'Dynamic Analysis Dashboard'!$B$11*'Dynamic Analysis Dashboard'!$B$9*'Dynamic Analysis Dashboard'!$B$21 -> 0 | AD203: =SUM(Z203:AC203) -> 1.485e-06 | AE203: =AD203*N203 -> 1.26225e-06
A204: Huge | B204: UC-08 | C204: Code Quality Assessment System | D204: Technology Delivery | E204: Code Review | F204: Coding Assistance, Data Analysis | G204: High | H204: Q1 | I204: 1.5e-06 | J204: 0 | K204: 1.2e-06 | L204: 0 | M204: 2.7e-06 | N204: 0.75 | O204: 6 | P204: 2 | Q204: 4 | R204: 2 | S204: 11780 | T204: 59.76 | U204: No cost impact | V204: N/A | W204: 35% defect reduction × $4.8M post-launch remediation × 0.80 × 0.75 = $1.0M rounded to $1.2M | X204: N/A | Y204: Technical leads review all critical and high-severity findings for business impact assessment before | Z204: =I204*'Dynamic Analysis Dashboard'!$B$8*'Dynamic Analysis Dashboard'!$B$9*'Dynamic Analysis Dashboard'!$B$21 -> 1.0125e-06 | AA204: =J204*'Dynamic Analysis Dashboard'!$B$8*'Dynamic Analysis Dashboard'!$B$9*'Dynamic Analysis Dashboard'!$B$21 -> 0 | AB204: =K204*'Dynamic Analysis Dashboard'!$B$10*'Dynamic Analysis Dashboard'!$B$9*'Dynamic Analysis Dashboard'!$B$21 -> 7.2e-07 | AC204: =L204*'Dynamic Analysis Dashboard'!$B$11*'Dynamic Analysis Dashboard'!$B$9*'Dynamic Analysis Dashboard'!$B$21 -> 0 | AD204: =SUM(Z204:AC204) -> 1.7325e-06 | AE204: =AD204*N204 -> 1.299375e-06
A205: Huge | B205: UC-02 | C205: Creative Asset Versioning Engine | D205: Creative Services | E205: Asset Production | F205: Content Creation, Workflow Automation | G205: Medium | H205: Q3 | I205: 3.4e-06 | J205: 0 | K205: 0 | L205: 1.3e-06 | M205: 4.7e-06 | N205: 0.8 | O205: 12 | P205: 3 | Q205: 3 | R205: 4 | S205: 26400 | T205: 36 | U205: No cost impact | V205: N/A | W205: N/A | X205: 7 days campaign acceleration × $52K daily revenue × 30 campaigns × 0.85 × 0.75 = $7.0M × 0.19 margin | Y205: Art directors review randomized samples of 15% of generated variants for brand compliance and qualit | Z205: =I205*'Dynamic Analysis Dashboard'!$B$8*'Dynamic Analysis Dashboard'!$B$9*'Dynamic Analysis Dashboard'!$B$21 -> 2.295e-06 | AA205: =J205*'Dynamic Analysis Dashboard'!$B$8*'Dynamic Analysis Dashboard'!$B$9*'Dynamic Analysis Dashboard'!$B$21 -> 0 | AB205: =K205*'Dynamic Analysis Dashboard'!$B$10*'Dynamic Analysis Dashboard'!$B$9*'Dynamic Analysis Dashboard'!$B$21 -> 0 | AC205: =L205*'Dynamic Analysis Dashboard'!$B$11*'Dynamic Analysis Dashboard'!$B$9*'Dynamic Analysis Dashboard'!$B$21 -> 8.2875e-07 | AD205: =SUM(Z205:AC205) -> 3.12375e-06 | AE205: =AD205*N205 -> 2.499e-06
A206: Huge | B206: UC-03 | C206: Scope Change Documentation System | D206: Project Management | E206: Scope Documentation | G206: Medium | H206: Q3 | I206: 2.8e-06 | J206: 0 | K206: 1.1e-06 | L206: 1.7e-06 | M206: 5.6e-06 | N206: 0.7 | O206: 12 | P206: 4 | Q206: 2 | R206: 4 | S206: 13600 | T206: 81.6 | U206: No cost impact | V206: N/A | W206: 12% reduction × $12M scope dispute exposure × 0.80 × 0.75 = $0.9M rounded to $1.1M | X206: 7 days change order acceleration × $41K daily revenue × 85 changes × 0.85 × 0.75 = $1.7M | Y206: Project managers review all AI-flagged scope changes for accuracy and business impact before initiat | Z206: =I206*'Dynamic Analysis Dashboard'!$B$8*'Dynamic Analysis Dashboard'!$B$9*'Dynamic Analysis Dashboard'!$B$21 -> 1.89e-06 | AA206: =J206*'Dynamic Analysis Dashboard'!$B$8*'Dynamic Analysis Dashboard'!$B$9*'Dynamic Analysis Dashboard'!$B$21 -> 0 | AB206: =K206*'Dynamic Analysis Dashboard'!$B$10*'Dynamic Analysis Dashboard'!$B$9*'Dynamic Analysis Dashboard'!$B$21 -> 6.6e-07 | AC206: =L206*'Dynamic Analysis Dashboard'!$B$11*'Dynamic Analysis Dashboard'!$B$9*'Dynamic Analysis Dashboard'!$B$21 -> 1.08375e-06 | AD206: =SUM(Z206:AC206) -> 3.63375e-06 | AE206: =AD206*N206 -> 2.543625e-06
A207: Huge | B207: UC-04 | C207: Consumer Insights Synthesis Platform | D207: Strategy & Planning | E207: Consumer Insights | F207: Research & Information Retrieval, Data Analysis | G207: Medium | H207: Q2 | I207: 4.1e-06 | J207: 0 | K207: 0 | L207: 0 | M207: 4.1e-06 | N207: 0.75 | O207: 9 | P207: 3 | Q207: 2 | R207: 3 | S207: 11280 | T207: 51.84 | U207: No cost impact | V207: N/A | W207: N/A | X207: N/A | Y207: Strategy leads validate statistical significance of identified patterns and assess cultural context | Z207: =I207*'Dynamic Analysis Dashboard'!$B$8*'Dynamic Analysis Dashboard'!$B$9*'Dynamic Analysis Dashboard'!$B$21 -> 2.7675e-06 | AA207: =J207*'Dynamic Analysis Dashboard'!$B$8*'Dynamic Analysis Dashboard'!$B$9*'Dynamic Analysis Dashboard'!$B$21 -> 0 | AB207: =K207*'Dynamic Analysis Dashboard'!$B$10*'Dynamic Analysis Dashboard'!$B$9*'Dynamic Analysis Dashboard'!$B$21 -> 0 | AC207: =L207*'Dynamic Analysis Dashboard'!$B$11*'Dynamic Analysis Dashboard'!$B$9*'Dynamic Analysis Dashboard'!$B$21 -> 0 | AD207: =SUM(Z207:AC207) -> 2.7675e-06 | AE207: =AD207*N207 -> 2.075625e-06
A208: Huge | B208: UC-05 | C208: Brand Compliance Guardian | D208: Creative Services | E208: Brand Compliance | F208: Data Analysis, Conversational Interfaces | G208: Medium | H208: Q2 | I208: 2.5e-06 | J208: 0 | K208: 8e-07 | L208: 0 | M208: 3.3e-06 | N208: 0.8 | O208: 6 | P208: 3 | Q208: 3 | R208: 3 | S208: 14400 | T208: 37.8 | U208: No cost impact | V208: N/A | W208: 18% reduction × $7M brand compliance incidents × 0.80 × 0.75 = $0.8M | X208: N/A | Y208: Creative directors review all flagged violations for severity assessment and make final determinatio | Z208: =I208*'Dynamic Analysis Dashboard'!$B$8*'Dynamic Analysis Dashboard'!$B$9*'Dynamic Analysis Dashboard'!$B$21 -> 1.6875e-06 | AA208: =J208*'Dynamic Analysis Dashboard'!$B$8*'Dynamic Analysis Dashboard'!$B$9*'Dynamic Analysis Dashboard'!$B$21 -> 0 | AB208: =K208*'Dynamic Analysis Dashboard'!$B$10*'Dynamic Analysis Dashboard'!$B$9*'Dynamic Analysis Dashboard'!$B$21 -> 4.8e-07 | AC208: =L208*'Dynamic Analysis Dashboard'!$B$11*'Dynamic Analysis Dashboard'!$B$9*'Dynamic Analysis Dashboard'!$B$21 -> 0 | AD208: =SUM(Z208:AC208) -> 2.1675e-06 | AE208: =AD208*N208 -> 1.734e-06
A209: Huge | B209: UC-07 | C209: Project Margin Forecasting Model | D209: Project Management | E209: Budget Forecasting | F209: Data Analysis, Workflow Automation | G209: Medium | H209: Q3 | I209: 1.8e-06 | J209: 0 | K209: 1.4e-06 | L209: 0 | M209: 3.2e-06 | N209: 0.7 | O209: 9 | P209: 3 | Q209: 3 | R209: 3 | S209: 7820 | T209: 43.92 | U209: No cost impact | V209: N/A | W209: 20% reduction × $9.3M margin variance exposure × 0.80 × 0.75 = $1.1M rounded to $1.4M | X209: N/A | Y209: Finance business partners review margin predictions for reasonableness and validate recommended inte | Z209: =I209*'Dynamic Analysis Dashboard'!$B$8*'Dynamic Analysis Dashboard'!$B$9*'Dynamic Analysis Dashboard'!$B$21 -> 1.215e-06 | AA209: =J209*'Dynamic Analysis Dashboard'!$B$8*'Dynamic Analysis Dashboard'!$B$9*'Dynamic Analysis Dashboard'!$B$21 -> 0 | AB209: =K209*'Dynamic Analysis Dashboard'!$B$10*'Dynamic Analysis Dashboard'!$B$9*'Dynamic Analysis Dashboard'!$B$21 -> 8.4e-07 | AC209: =L209*'Dynamic Analysis Dashboard'!$B$11*'Dynamic Analysis Dashboard'!$B$9*'Dynamic Analysis Dashboard'!$B$21 -> 0 | AD209: =SUM(Z209:AC209) -> 2.055e-06 | AE209: =AD209*N209 -> 1.4385e-06
A210: Huge | B210: UC-09 | C210: Onboarding Knowledge Assistant | D210: Talent Development | E210: Onboarding | F210: Research & Information Retrieval, Conversational Interfaces, Content Creation | G210: Medium | H210: Q2 | I210: 2.6e-06 | J210: 0 | K210: 0 | L210: 0 | M210: 2.6e-06 | N210: 0.7 | O210: 9 | P210: 2 | Q210: 2 | R210: 2 | S210: 6600 | T210: 30.6 | U210: No cost impact | V210: N/A | W210: N/A | X210: N/A | Y210: Talent development managers review AI-generated learning paths for role appropriateness and monitor | Z210: =I210*'Dynamic Analysis Dashboard'!$B$8*'Dynamic Analysis Dashboard'!$B$9*'Dynamic Analysis Dashboard'!$B$21 -> 1.755e-06 | AA210: =J210*'Dynamic Analysis Dashboard'!$B$8*'Dynamic Analysis Dashboard'!$B$9*'Dynamic Analysis Dashboard'!$B$21 -> 0 | AB210: =K210*'Dynamic Analysis Dashboard'!$B$10*'Dynamic Analysis Dashboard'!$B$9*'Dynamic Analysis Dashboard'!$B$21 -> 0 | AC210: =L210*'Dynamic Analysis Dashboard'!$B$11*'Dynamic Analysis Dashboard'!$B$9*'Dynamic Analysis Dashboard'!$B$21 -> 0 | AD210: =SUM(Z210:AC210) -> 1.755e-06 | AE210: =AD210*N210 -> 1.2285e-06
A211: Huge | B211: UC-10 | C211: Contract Intelligence Platform | D211: Legal & Compliance | E211: Contract Redlining | F211: Research & Information Retrieval, Data Analysis, Content Creation | G211: Medium | H211: Q2 | I211: 9e-07 | J211: 0 | K211: 6e-07 | L211: 1.1e-06 | M211: 2.6e-06 | N211: 0.75 | O211: 6 | P211: 3 | Q211: 3 | R211: 2 | S211: 2688 | T211: 20.736 | U211: No cost impact | V211: N/A | W211: 14% reduction × $6.2M contract dispute exposure × 0.80 × 0.75 = $0.5M rounded to $0.6M | X211: 5 days contract acceleration × $37K daily revenue × 48 new clients × 0.85 × 0.75 = $1.1M | Y211: Legal counsel reviews all AI-suggested contract language before client submission and approves risk | Z211: =I211*'Dynamic Analysis Dashboard'!$B$8*'Dynamic Analysis Dashboard'!$B$9*'Dynamic Analysis Dashboard'!$B$21 -> 6.075e-07 | AA211: =J211*'Dynamic Analysis Dashboard'!$B$8*'Dynamic Analysis Dashboard'!$B$9*'Dynamic Analysis Dashboard'!$B$21 -> 0 | AB211: =K211*'Dynamic Analysis Dashboard'!$B$10*'Dynamic Analysis Dashboard'!$B$9*'Dynamic Analysis Dashboard'!$B$21 -> 3.6e-07 | AC211: =L211*'Dynamic Analysis Dashboard'!$B$11*'Dynamic Analysis Dashboard'!$B$9*'Dynamic Analysis Dashboard'!$B$21 -> 7.0125e-07 | AD211: =SUM(Z211:AC211) -> 1.66875e-06 | AE211: =AD211*N211 -> 1.2515625e-06
A212: Impetus Wellness | B212: UC-01 | C212: Biometric Data Normalization Engine | D212: Clinical Operations | E212: Biometric Data Processing | F212: Data Analysis, Workflow Automation | G212: High | H212: Q1 | I212: 1.7e-05 | J212: 0 | K212: 1.8e-06 | L212: 0 | M212: 1.88e-05 | N212: 0.85 | O212: 9 | P212: 4 | Q212: 3 | R212: 4 | S212: 420000 | T212: 228.6 | U212: 18,500 hours × $125/hour × 75% time reduction × 0.90 × 0.75 = $17.0M | V212: No direct revenue impact | W212: 15% reduction × $15M data quality exposure × 0.80 × 0.75 = $1.8M | X212: No direct cash flow impact | Y212: Clinical quality assurance specialists review and approve all flagged data anomalies and outlier val | Z212: =I212*'Dynamic Analysis Dashboard'!$B$8*'Dynamic Analysis Dashboard'!$B$9*'Dynamic Analysis Dashboard'!$B$21 -> 1.1475e-05 | AA212: =J212*'Dynamic Analysis Dashboard'!$B$8*'Dynamic Analysis Dashboard'!$B$9*'Dynamic Analysis Dashboard'!$B$21 -> 0 | AB212: =K212*'Dynamic Analysis Dashboard'!$B$10*'Dynamic Analysis Dashboard'!$B$9*'Dynamic Analysis Dashboard'!$B$21 -> 1.08e-06 | AC212: =L212*'Dynamic Analysis Dashboard'!$B$11*'Dynamic Analysis Dashboard'!$B$9*'Dynamic Analysis Dashboard'!$B$21 -> 0 | AD212: =SUM(Z212:AC212) -> 1.2555e-05 | AE212: =AD212*N212 -> 1.067175e-05
A213: Impetus Wellness | B213: UC-02 | C213: Real-Time Health Insight Generator | D213: Clinical Operations | E213: Health Risk Assessment | F213: Data Analysis, Content Creation, Research & Information Retrieval | G213: High | H213: Q2 | I213: 0 | J213: 1.21e-05 | K213: 2.7e-06 | L213: 0 | M213: 1.48e-05 | N213: 0.75 | O213: 12 | P213: 4 | Q213: 3 | R213: 4 | S213: 299600 | T213: 611.28 | U213: No direct cost impact | V213: 14 percentage point engagement lift × $180M revenue × 0.48 revenue correlation × 0.95 × 0.75 = $12.1 | W213: 25% reduction × $18M undetected high-risk exposure × 0.80 × 0.75 = $2.7M | X213: No direct cash flow impact | Y213: Licensed health coaches review and approve all clinical recommendations and member-facing health gui | Z213: =I213*'Dynamic Analysis Dashboard'!$B$8*'Dynamic Analysis Dashboard'!$B$9*'Dynamic Analysis Dashboard'!$B$21 -> 0 | AA213: =J213*'Dynamic Analysis Dashboard'!$B$8*'Dynamic Analysis Dashboard'!$B$9*'Dynamic Analysis Dashboard'!$B$21 -> 8.1675e-06 | AB213: =K213*'Dynamic Analysis Dashboard'!$B$10*'Dynamic Analysis Dashboard'!$B$9*'Dynamic Analysis Dashboard'!$B$21 -> 1.62e-06 | AC213: =L213*'Dynamic Analysis Dashboard'!$B$11*'Dynamic Analysis Dashboard'!$B$9*'Dynamic Analysis Dashboard'!$B$21 -> 0 | AD213: =SUM(Z213:AC213) -> 9.7875e-06 | AE213: =AD213*N213 -> 7.340625e-06
...

Sheet 4. Benefits by Driver
A1: BENEFITS ANALYSIS BY DRIVER
A3: SUMMARY BY BENEFIT TYPE
A4: Benefit Type | B4: Total Value ($M) | C4: % of Total | D4: Use Cases with Impact
A5: Cost Savings | B5: 169.05149 | C5: 0.43458678 | D5: 482
A6: Revenue Growth | B6: 148.10122 | C6: 0.38072917 | D6: 208
A7: Risk Reduction | B7: 65.960392 | C7: 0.16956677 | D7: 225
A8: Cash Flow Acceleration | B8: 57.370511 | C8: 0.14748445 | D8: 145
A10: BY FUNCTION
A11: Function | B11: Cost ($M) | C11: Revenue ($M) | D11: Risk ($M) | E11: Cash Flow ($M) | F11: Total ($M)
A12: Account Management | B12: 0 | C12: 2.43e-05 | D12: 0.8 | E12: 0 | F12: 2.51e-05
A13: Administrative | B13: 0.4 | C13: 0 | D13: 0.4 | E13: 0 | F13: 0.8
A14: Agent Development | B14: 3.5e-06 | C14: 1.13e-05 | D14: 0 | E14: 0 | F14: 1.48e-05
A15: Asset Management | B15: 0.7 | C15: 0 | D15: 0.3000012 | E15: 1.4e-06 | F15: 0.600003
A16: Business Development | B16: 6.5000212 | C16: 3.8000753 | D16: 6e-07 | E16: 0.8 | F16: 9.8000955
A17: Business Intelligence | B17: 1.2e-06 | C17: 0 | D17: 0 | E17: 0 | F17: 1.2e-06
A18: Carrier Management | B18: 2.45e-05 | C18: 0 | D18: 6.3e-06 | E18: 2.8e-06 | F18: 3.36e-05
A19: Claims | B19: 5.8e-06 | C19: 0 | D19: 8e-07 | E19: 4.3e-06 | F19: 1.09e-05
A20: Client Communications | B20: 2.1 | C20: 0 | D20: 0 | E20: 0 | F20: 2.1
A21: Client Delivery | B21: 4.5e-06 | C21: 0 | D21: 0.9000012 | E21: 1e-06 | F21: 0.9000067
A22: Client Management | B22: 0.9000016 | C22: 0 | D22: 0.6 | E22: 1.4e-06 | F22: 4.5e-06
A23: Client Relationship Management | B23: 2.9 | C23: 11.8 | D23: 0 | E23: 0 | F23: 14.7
... A135: Utilization Management | B135: 1.6 | C135: 0.5 | D135: 0.1 | E135: 0.6 | F135: 2.8
A137: BY PRIORITY TIER
A138: Priority | B138: Use Cases | C138: Cost ($M) | D138: Revenue ($M) | E138: Risk ($M) | F138: Cash Flow ($M) | G138: Total ($M)
A139: Critical | B139: 111 | C139: 46.600397 | D139: 46.700606 | E139: 6.000089 | F139: 3.7801721 | G139: 98.70126
A140: High | B140: 247 | C140: 92.790659 | D140: 84.20038 | E140: 43.500208 | F140: 35.700194 | G140: 235.40146
A141: Medium | B141: 182 | C141: 29.66043 | D141: 17.200233 | E141: 16.460096 | F141: 17.890145 | G141: 54.890904

Sheet 5. KPI Baselines
A1: Company | B1: Function | C1: Sub-Function | D1: KPI Name | E1: Baseline Value | F1: Target Value | G1: Industry Benchmark | H1: Direction | I1: Timeframe | J1: Measurement Method
A2: 50 Floor | B2: Sales Operations | C2: In-Home Consultations | D2: Appointment Close Rate | E2: 68% | F2: 75% | G2: 72% | H2: ↑ | I2: 12 months | J2: Closed sales / qualified appointments scheduled
A3: 50 Floor | B3: Sales Operations | C3: Lead Management | D3: Customer Acquisition Cost | E3: $420 | F3: $380 | G3: $385 | H3: ↓ | I3: 12 months | J3: Total marketing spend / closed sales
A4: 50 Floor | B4: Installation Coordination | C4: Measurement Validation | D4: Material Waste Rate | E4: 8.2% | F4: 3.0% | G4: 4.5% | H4: ↓ | I4: 9 months | J4: Excess material cost / total material cost
A5: 50 Floor | B5: Installation Coordination | C5: Scheduling | D5: Average Days to Installation | E5: 6 days | F5: 2 days | G5: 3 days | H5: ↓ | I5: 9 months | J5: Calendar days from order to installation start
A6: 50 Floor | B6: Customer Service | C6: Inquiry Resolution | D6: Average Response Time (Peak) | E6: 18 hours | F6: 4 hours | G6: 6 hours | H6: ↓ | I6: 6 months | J6: Time from inquiry receipt to first response
A7: 50 Floor | B7: Customer Service | C7: Inquiry Resolution | D7: Routine Inquiry Deflection Rate | E7: 12% | F7: 60% | G7: 45% | H7: ↑ | I7: 6 months | J7: Self-service resolutions / total inquiries
A8: 50 Floor | B8: Procurement | C8: Supplier Coordination | D8: Order-to-Delivery Cycle Time | E8: 12 days | F8: 7 days | G8: 8 days | H8: ↓ | I8: 12 months | J8: Days from purchase order to material receipt
A9: 50 Floor | B9: Finance | C9: Accounts Payable | D9: Invoice Processing Time | E9: 8 days | F9: 2 days | G9: 3 days | H9: ↓ | I9: 6 months | J9: Days from invoice receipt to payment approval
A10: 50 Floor | B10: Quality Assurance | C10: Pre-Installation Review | D10: Measurement Review Hours | E10: 18,500 hours/year | F10: 5,000 hours/year | G10: Not Available | H10: ↓ | I10: 9 months | J10: Manager hours spent on measurement validation
